Workbook

Sheet UAT
A1: BILL_TYPE_ID | B1: BILL_TYPE | C1: SUB_BILL_TYPE_ID | D1: SUB_BILL_TYPE | E1: Bill ID In UAT Bill type ID Sheet ? | F1: UAT Bill ID in LIVE? | G1: UAT Bill NAME in LIVE? | H1: UAT Sub Bill ID in LIVE | I1: UAT Sub Bill Name in LIVE
A2: 1000028 | B2: auto BT 01 | C2: 1000031 | D2: auto SBT 01 | E2: =VLOOKUP(A:A,[1]Sheet1!$A:$A,1,0) -> #N/A | F2: =VLOOKUP(A:A,'[2]Final sheet'!$A$1:$A$65536,1,0) -> #N/A | G2: =VLOOKUP(B:B,'[2]Final sheet'!$B$1:$B$65536,1,0) -> #N/A | H2: =VLOOKUP(C:C,'[2]Final sheet'!$D$1:$D$65536,1,0) -> #N/A | I2: =VLOOKUP(D:D,'[2]Final sheet'!$D$1:$D$65536,1,0) -> #N/A
A3: 1000029 | B3: auto BT 02 | C3: 1000032 | D3: auto SBT 02 | E3: =VLOOKUP(A:A,[1]Sheet1!$A:$A,1,0) -> #N/A | F3: =VLOOKUP(A:A,'[2]Final sheet'!$A$1:$A$65536,1,0) -> #N/A | G3: =VLOOKUP(B:B,'[2]Final sheet'!$B$1:$B$65536,1,0) -> #N/A | H3: =VLOOKUP(C:C,'[2]Final sheet'!$D$1:$D$65536,1,0) -> #N/A | I3: =VLOOKUP(D:D,'[2]Final sheet'!$D$1:$D$65536,1,0) -> #N/A
A4: 1000030 | B4: auto BT 03 | C4: 1000033 | D4: auto SBT 03 | E4: =VLOOKUP(A:A,[1]Sheet1!$A:$A,1,0) -> #N/A | F4: =VLOOKUP(A:A,'[2]Final sheet'!$A$1:$A$65536,1,0) -> #N/A | G4: =VLOOKUP(B:B,'[2]Final sheet'!$B$1:$B$65536,1,0) -> #N/A | H4: =VLOOKUP(C:C,'[2]Final sheet'!$D$1:$D$65536,1,0) -> #N/A | I4: =VLOOKUP(D:D,'[2]Final sheet'!$D$1:$D$65536,1,0) -> #N/A
A5: 500528 | B5: Anesthetist Charges | C5: 702121 | D5: Dental Anesthetist | E5: =VLOOKUP(A:A,[1]Sheet1!$A:$A,1,0) -> 500528 | F5: =VLOOKUP(A:A,'[2]Final sheet'!$A$1:$A$65536,1,0) -> 500528 | G5: =VLOOKUP(B:B,'[2]Final sheet'!$B$1:$B$65536,1,0) -> Anesthetist Charges | H5: =VLOOKUP(C:C,'[2]Final sheet'!$D$1:$D$65536,1,0) -> #N/A | I5: =VLOOKUP(D:D,'[2]Final sheet'!$D$1:$D$65536,1,0) -> #N/A
A6: 500531 | B6: Assistant Surgeon Charges | C6: 702088 | D6: Room Rent charges | E6: =VLOOKUP(A:A,[1]Sheet1!$A:$A,1,0) -> 500531 | F6: =VLOOKUP(A:A,'[2]Final sheet'!$A$1:$A$65536,1,0) -> 500531 | G6: =VLOOKUP(B:B,'[2]Final sheet'!$B$1:$B$65536,1,0) -> Assistant Surgeon Charges | H6: =VLOOKUP(C:C,'[2]Final sheet'!$D$1:$D$65536,1,0) -> #N/A | I6: =VLOOKUP(D:D,'[2]Final sheet'!$D$1:$D$65536,1,0) -> #N/A
A7: 500531 | B7: Assistant Surgeon Charges | C7: 702090 | D7: Sub Bill Room Rent Charges | E7: =VLOOKUP(A:A,[1]Sheet1!$A:$A,1,0) -> 500531 | F7: =VLOOKUP(A:A,'[2]Final sheet'!$A$1:$A$65536,1,0) -> 500531 | G7: =VLOOKUP(B:B,'[2]Final sheet'!$B$1:$B$65536,1,0) -> Assistant Surgeon Charges | H7: =VLOOKUP(C:C,'[2]Final sheet'!$D$1:$D$65536,1,0) -> #N/A | I7: =VLOOKUP(D:D,'[2]Final sheet'!$D$1:$D$65536,1,0) -> #N/A
A8: 500528 | B8: Anesthetist Charges | C8: 702034 | D8: Rampaul | E8: =VLOOKUP(A:A,[1]Sheet1!$A:$A,1,0) -> 500528 | F8: =VLOOKUP(A:A,'[2]Final sheet'!$A$1:$A$65536,1,0) -> 500528 | G8: =VLOOKUP(B:B,'[2]Final sheet'!$B$1:$B$65536,1,0) -> Anesthetist Charges | H8: =VLOOKUP(C:C,'[2]Final sheet'!$D$1:$D$65536,1,0) -> #N/A | I8: =VLOOKUP(D:D,'[2]Final sheet'!$D$1:$D$65536,1,0) -> #N/A
A9: 500534 | B9: Consumable Charges | C9: 702035 | D9: CC1 | E9: =VLOOKUP(A:A,[1]Sheet1!$A:$A,1,0) -> 500534 | F9: =VLOOKUP(A:A,'[2]Final sheet'!$A$1:$A$65536,1,0) -> 500534 | G9: =VLOOKUP(B:B,'[2]Final sheet'!$B$1:$B$65536,1,0) -> Consumable Charges | H9: =VLOOKUP(C:C,'[2]Final sheet'!$D$1:$D$65536,1,0) -> #N/A | I9: =VLOOKUP(D:D,'[2]Final sheet'!$D$1:$D$65536,1,0) -> #N/A
A10: 500534 | B10: Consumable Charges | C10: 702036 | D10: CC2 | E10: =VLOOKUP(A:A,[1]Sheet1!$A:$A,1,0) -> 500534 | F10: =VLOOKUP(A:A,'[2]Final sheet'!$A$1:$A$65536,1,0) -> 500534 | G10: =VLOOKUP(B:B,'[2]Final sheet'!$B$1:$B$65536,1,0) -> Consumable Charges | H10: =VLOOKUP(C:C,'[2]Final sheet'!$D$1:$D$65536,1,0) -> #N/A | I10: =VLOOKUP(D:D,'[2]Final sheet'!$D$1:$D$65536,1,0) -> #N/A
A11: 500535 | B11: Investigation Charges | C11: 702039 | D11: I1 | E11: =VLOOKUP(A:A,[1]Sheet1!$A:$A,1,0) -> 500535 | F11: =VLOOKUP(A:A,'[2]Final sheet'!$A$1:$A$65536,1,0) -> 500535 | G11: =VLOOKUP(B:B,'[2]Final sheet'!$B$1:$B$65536,1,0) -> Investigation Charges | H11: =VLOOKUP(C:C,'[2]Final sheet'!$D$1:$D$65536,1,0) -> #N/A | I11: =VLOOKUP(D:D,'[2]Final sheet'!$D$1:$D$65536,1,0) -> #N/A
A12: 702040 | B12: KD Anesthetist Charges | C12: 702047 | D12: KD Dental Anesthetist Charges | E12: =VLOOKUP(A:A,[1]Sheet1!$A:$A,1,0) -> #N/A | F12: =VLOOKUP(A:A,'[2]Final sheet'!$A$1:$A$65536,1,0) -> #N/A | G12: =VLOOKUP(B:B,'[2]Final sheet'!$B$1:$B$65536,1,0) -> #N/A | H12: =VLOOKUP(C:C,'[2]Final sheet'!$D$1:$D$65536,1,0) -> #N/A | I12: =VLOOKUP(D:D,'[2]Final sheet'!$D$1:$D$65536,1,0) -> #N/A
A13: 702040 | B13: KD Anesthetist Charges | C13: 702048 | D13: KD Local Anesthetist Charges | E13: =VLOOKUP(A:A,[1]Sheet1!$A:$A,1,0) -> #N/A | F13: =VLOOKUP(A:A,'[2]Final sheet'!$A$1:$A$65536,1,0) -> #N/A | G13: =VLOOKUP(B:B,'[2]Final sheet'!$B$1:$B$65536,1,0) -> #N/A | H13: =VLOOKUP(C:C,'[2]Final sheet'!$D$1:$D$65536,1,0) -> #N/A | I13: =VLOOKUP(D:D,'[2]Final sheet'!$D$1:$D$65536,1,0) -> #N/A
... A135: 500537 | B135: Taxes | C135: 1003383 | D135: Taxes | E135: =VLOOKUP(A:A,[1]Sheet1!$A:$A,1,0) -> 500537 | F135: =VLOOKUP(A:A,'[2]Final sheet'!$A$1:$A$65536,1,0) -> 500537 | G135: =VLOOKUP(B:B,'[2]Final sheet'!$B$1:$B$65536,1,0) -> Taxes | H135: =VLOOKUP(C:C,'[2]Final sheet'!$D$1:$D$65536,1,0) -> #N/A | I135: =VLOOKUP(D:D,'[2]Final sheet'!$D$1:$D$65536,1,0) -> #N/A

Sheet Live
A1: PARENT ID | B1: MAIN BILL TYPE | C1: SUB BILL TYPE | D1: SUB BILL TYPE ID | E1: Bill ID in UAT ? | F1: Bill Name in UAT ? | G1: Sub Bill ID in UAT ? | H1: Sub Bill Name in UAT ?
A2: 1011057 | B2: Alpha Bed charges | C2: Alpha bed | D2: 1000751 | E2: =VLOOKUP(A:A,UAT!A:A,1,0) -> #N/A | F2: =VLOOKUP(B:B,UAT!B:B,1,0) -> Alpha Bed charges | G2: =VLOOKUP(D:D,UAT!C:C,1,0) -> #N/A | H2: =VLOOKUP(C:C,UAT!D:D,1,0) -> #N/A
C3: Nimbus bed | D3: 1014398 | E3: =VLOOKUP(A:A,UAT!A:A,1,0) -> #N/A | F3: =VLOOKUP(B:B,UAT!B:B,1,0) -> #N/A | G3: =VLOOKUP(D:D,UAT!C:C,1,0) -> #N/A | H3: =VLOOKUP(C:C,UAT!D:D,1,0) -> #N/A
C4: Water bed | D4: 1011072 | E4: =VLOOKUP(A:A,UAT!A:A,1,0) -> #N/A | F4: =VLOOKUP(B:B,UAT!B:B,1,0) -> #N/A | G4: =VLOOKUP(D:D,UAT!C:C,1,0) -> #N/A | H4: =VLOOKUP(C:C,UAT!D:D,1,0) -> Water Bed
C5: Air mattress | D5: 1014374 | E5: =VLOOKUP(A:A,UAT!A:A,1,0) -> #N/A | F5: =VLOOKUP(B:B,UAT!B:B,1,0) -> #N/A | G5: =VLOOKUP(D:D,UAT!C:C,1,0) -> #N/A | H5: =VLOOKUP(C:C,UAT!D:D,1,0) -> #N/A
A6: 1011054 | B6: Ambulance Charges | C6: Ambulance charges | D6: 1011068 | E6: =VLOOKUP(A:A,UAT!A:A,1,0) -> #N/A | F6: =VLOOKUP(B:B,UAT!B:B,1,0) -> Ambulance Charges | G6: =VLOOKUP(D:D,UAT!C:C,1,0) -> #N/A | H6: =VLOOKUP(C:C,UAT!D:D,1,0) -> Ambulance Charges
A7: 500528 | B7: Anesthetist Charges | C7: Anesthetist charges | D7: 706035 | E7: =VLOOKUP(A:A,UAT!A:A,1,0) -> 500528 | F7: =VLOOKUP(B:B,UAT!B:B,1,0) -> Anesthetist Charges | G7: =VLOOKUP(D:D,UAT!C:C,1,0) -> #N/A | H7: =VLOOKUP(C:C,UAT!D:D,1,0) -> Anesthetist Charges
A8: 1011056 | B8: Anesthesia Charges | C8: Anesthesia Charges | D8: 1011684 | E8: =VLOOKUP(A:A,UAT!A:A,1,0) -> #N/A | F8: =VLOOKUP(B:B,UAT!B:B,1,0) -> Anesthesia Charges | G8: =VLOOKUP(D:D,UAT!C:C,1,0) -> #N/A | H8: =VLOOKUP(C:C,UAT!D:D,1,0) -> Anesthesia Charges
A9: 705926 | B9: Assistant Charges | C9: Assistant charges | D9: 1011676 | E9: =VLOOKUP(A:A,UAT!A:A,1,0) -> #N/A | F9: =VLOOKUP(B:B,UAT!B:B,1,0) -> #N/A | G9: =VLOOKUP(D:D,UAT!C:C,1,0) -> #N/A | H9: =VLOOKUP(C:C,UAT!D:D,1,0) -> Assistant Charges
A10: 1011058 | B10: Assistant Doctor Charges | C10: Assistant Doctor Charges | D10: 1014375 | E10: =VLOOKUP(A:A,UAT!A:A,1,0) -> #N/A | F10: =VLOOKUP(B:B,UAT!B:B,1,0) -> Assistant Doctor Charges | G10: =VLOOKUP(D:D,UAT!C:C,1,0) -> #N/A | H10: =VLOOKUP(C:C,UAT!D:D,1,0) -> #N/A
A11: 500531 | B11: Assistant Surgeon Charges | C11: Assistant Surgeon Charges | D11: 706037 | E11: =VLOOKUP(A:A,UAT!A:A,1,0) -> 500531 | F11: =VLOOKUP(B:B,UAT!B:B,1,0) -> Assistant Surgeon Charges | G11: =VLOOKUP(D:D,UAT!C:C,1,0) -> #N/A | H11: =VLOOKUP(C:C,UAT!D:D,1,0) -> Assistant Surgeon Charges
A12: 500529 | B12: Consultation Visit Charges | C12: Consultation charges | D12: 1011073 | E12: =VLOOKUP(A:A,UAT!A:A,1,0) -> #N/A | F12: =VLOOKUP(B:B,UAT!B:B,1,0) -> #N/A | G12: =VLOOKUP(D:D,UAT!C:C,1,0) -> #N/A | H12: =VLOOKUP(C:C,UAT!D:D,1,0) -> Consultation charges
C13: Doctor Visit Charges | D13: 706043 | E13: =VLOOKUP(A:A,UAT!A:A,1,0) -> #N/A | F13: =VLOOKUP(B:B,UAT!B:B,1,0) -> #N/A | G13: =VLOOKUP(D:D,UAT!C:C,1,0) -> #N/A | H13: =VLOOKUP(C:C,UAT!D:D,1,0) -> #N/A
A14: 500534 | B14: Consumable Charges | C14: Consumables | D14: 1000775 | E14: =VLOOKUP(A:A,UAT!A:A,1,0) -> 500534 | F14: =VLOOKUP(B:B,UAT!B:B,1,0) -> Consumable Charges | G14: =VLOOKUP(D:D,UAT!C:C,1,0) -> #N/A | H14: =VLOOKUP(C:C,UAT!D:D,1,0) -> Consumables
C15: Disposables | D15: 1011077 | E15: =VLOOKUP(A:A,UAT!A:A,1,0) -> #N/A | F15: =VLOOKUP(B:B,UAT!B:B,1,0) -> #N/A | G15: =VLOOKUP(D:D,UAT!C:C,1,0) -> #N/A | H15: =VLOOKUP(C:C,UAT!D:D,1,0) -> Disposables
C16: Materials | D16: 1011076 | E16: =VLOOKUP(A:A,UAT!A:A,1,0) -> #N/A | F16: =VLOOKUP(B:B,UAT!B:B,1,0) -> #N/A | G16: =VLOOKUP(D:D,UAT!C:C,1,0) -> #N/A | H16: =VLOOKUP(C:C,UAT!D:D,1,0) -> Materials
C17: OT consumables | D17: 1000770 | E17: =VLOOKUP(A:A,UAT!A:A,1,0) -> #N/A | F17: =VLOOKUP(B:B,UAT!B:B,1,0) -> #N/A | G17: =VLOOKUP(D:D,UAT!C:C,1,0) -> #N/A | H17: =VLOOKUP(C:C,UAT!D:D,1,0) -> #N/A
C18: OT Materials | D18: 1014363 | E18: =VLOOKUP(A:A,UAT!A:A,1,0) -> #N/A | F18: =VLOOKUP(B:B,UAT!B:B,1,0) -> #N/A | G18: =VLOOKUP(D:D,UAT!C:C,1,0) -> #N/A | H18: =VLOOKUP(C:C,UAT!D:D,1,0) -> #N/A
C19: OT Gases | D19: 1000772 | E19: =VLOOKUP(A:A,UAT!A:A,1,0) -> #N/A | F19: =VLOOKUP(B:B,UAT!B:B,1,0) -> #N/A | G19: =VLOOKUP(D:D,UAT!C:C,1,0) -> #N/A | H19: =VLOOKUP(C:C,UAT!D:D,1,0) -> #N/A
C20: Oxygen charges | D20: 1011075 | E20: =VLOOKUP(A:A,UAT!A:A,1,0) -> #N/A | F20: =VLOOKUP(B:B,UAT!B:B,1,0) -> #N/A | G20: =VLOOKUP(D:D,UAT!C:C,1,0) -> #N/A | H20: =VLOOKUP(C:C,UAT!D:D,1,0) -> Oxygen Charges
C21: CSSD charges | D21: 1014376 | E21: =VLOOKUP(A:A,UAT!A:A,1,0) -> #N/A | F21: =VLOOKUP(B:B,UAT!B:B,1,0) -> #N/A | G21: =VLOOKUP(D:D,UAT!C:C,1,0) -> #N/A | H21: =VLOOKUP(C:C,UAT!D:D,1,0) -> #N/A
C22: PPE kit charges | D22: 1014377 | E22: =VLOOKUP(A:A,UAT!A:A,1,0) -> #N/A | F22: =VLOOKUP(B:B,UAT!B:B,1,0) -> #N/A | G22: =VLOOKUP(D:D,UAT!C:C,1,0) -> #N/A | H22: =VLOOKUP(C:C,UAT!D:D,1,0) -> #N/A
C23: Cost of Dialyser | D23: 1014378 | E23: =VLOOKUP(A:A,UAT!A:A,1,0) -> #N/A | F23: =VLOOKUP(B:B,UAT!B:B,1,0) -> #N/A | G23: =VLOOKUP(D:D,UAT!C:C,1,0) -> #N/A | H23: =VLOOKUP(C:C,UAT!D:D,1,0) -> #N/A
A24: 1011059 | B24: Cost of Implant | C24: implants | D24: 1000778 | E24: =VLOOKUP(A:A,UAT!A:A,1,0) -> #N/A | F24: =VLOOKUP(B:B,UAT!B:B,1,0) -> #N/A | G24: =VLOOKUP(D:D,UAT!C:C,1,0) -> #N/A | H24: =VLOOKUP(C:C,UAT!D:D,1,0) -> #N/A
C25: Stents | D25: 1000779 | E25: =VLOOKUP(A:A,UAT!A:A,1,0) -> #N/A | F25: =VLOOKUP(B:B,UAT!B:B,1,0) -> #N/A | G25: =VLOOKUP(D:D,UAT!C:C,1,0) -> #N/A | H25: =VLOOKUP(C:C,UAT!D:D,1,0) -> #N/A
C26: Intra Ocular Lense IOL | D26: 1011079 | E26: =VLOOKUP(A:A,UAT!A:A,1,0) -> #N/A | F26: =VLOOKUP(B:B,UAT!B:B,1,0) -> #N/A | G26: =VLOOKUP(D:D,UAT!C:C,1,0) -> #N/A | H26: =VLOOKUP(C:C,UAT!D:D,1,0) -> #N/A
C27: Mesh | D27: 1014379 | E27: =VLOOKUP(A:A,UAT!A:A,1,0) -> #N/A | F27: =VLOOKUP(B:B,UAT!B:B,1,0) -> #N/A | G27: =VLOOKUP(D:D,UAT!C:C,1,0) -> #N/A | H27: =VLOOKUP(C:C,UAT!D:D,1,0) -> #N/A
A28: 1000678 | B28: Doctor Home Visit | C28: Doctor Home Visit | D28: 1014380 | E28: =VLOOKUP(A:A,UAT!A:A,1,0) -> #N/A | F28: =VLOOKUP(B:B,UAT!B:B,1,0) -> #N/A | G28: =VLOOKUP(D:D,UAT!C:C,1,0) -> #N/A | H28: =VLOOKUP(C:C,UAT!D:D,1,0) -> #N/A
A29: 705929 | B29: Equipment charges | C29: Equipment charges | D29: 706044 | E29: =VLOOKUP(A:A,UAT!A:A,1,0) -> #N/A | F29: =VLOOKUP(B:B,UAT!B:B,1,0) -> Equipment charges | G29: =VLOOKUP(D:D,UAT!C:C,1,0) -> #N/A | H29: =VLOOKUP(C:C,UAT!D:D,1,0) -> Equipment charges
C30: Infusion Pump Charges | D30: 1014360 | E30: =VLOOKUP(A:A,UAT!A:A,1,0) -> #N/A | F30: =VLOOKUP(B:B,UAT!B:B,1,0) -> #N/A | G30: =VLOOKUP(D:D,UAT!C:C,1,0) -> #N/A | H30: =VLOOKUP(C:C,UAT!D:D,1,0) -> Infusion Pump Charges
C31: Ventilator | D31: 1000762 | E31: =VLOOKUP(A:A,UAT!A:A,1,0) -> #N/A | F31: =VLOOKUP(B:B,UAT!B:B,1,0) -> #N/A | G31: =VLOOKUP(D:D,UAT!C:C,1,0) -> #N/A | H31: =VLOOKUP(C:C,UAT!D:D,1,0) -> Ventilator
C32: Cardiac Monitor | D32: 1000752 | E32: =VLOOKUP(A:A,UAT!A:A,1,0) -> #N/A | F32: =VLOOKUP(B:B,UAT!B:B,1,0) -> #N/A | G32: =VLOOKUP(D:D,UAT!C:C,1,0) -> #N/A | H32: =VLOOKUP(C:C,UAT!D:D,1,0) -> #N/A
C33: Laproscope | D33: 1000768 | E33: =VLOOKUP(A:A,UAT!A:A,1,0) -> #N/A | F33: =VLOOKUP(B:B,UAT!B:B,1,0) -> #N/A | G33: =VLOOKUP(D:D,UAT!C:C,1,0) -> #N/A | H33: =VLOOKUP(C:C,UAT!D:D,1,0) -> Laproscope
C34: Pulse Oximeter | D34: 1000760 | E34: =VLOOKUP(A:A,UAT!A:A,1,0) -> #N/A | F34: =VLOOKUP(B:B,UAT!B:B,1,0) -> #N/A | G34: =VLOOKUP(D:D,UAT!C:C,1,0) -> #N/A | H34: =VLOOKUP(C:C,UAT!D:D,1,0) -> #N/A
A35: 1000861 | B35: Gym or lens or Spa or Food supplement | C35: Gym or lens or Spa or Food supplement | D35: 1014381 | E35: =VLOOKUP(A:A,UAT!A:A,1,0) -> #N/A | F35: =VLOOKUP(B:B,UAT!B:B,1,0) -> #N/A | G35: =VLOOKUP(D:D,UAT!C:C,1,0) -> #N/A | H35: =VLOOKUP(C:C,UAT!D:D,1,0) -> #N/A
A36: 705568 | B36: Hospital Daily Cash | C36: Hospital Daily Cash | D36: 706045 | E36: =VLOOKUP(A:A,UAT!A:A,1,0) -> #N/A | F36: =VLOOKUP(B:B,UAT!B:B,1,0) -> Hospital Daily Cash | G36: =VLOOKUP(D:D,UAT!C:C,1,0) -> #N/A | H36: =VLOOKUP(C:C,UAT!D:D,1,0) -> Hospital Daily Cash
A37: 1000740 | B37: ICU Charges | C37: ICU Rent | D37: 1011046 | E37: =VLOOKUP(A:A,UAT!A:A,1,0) -> #N/A | F37: =VLOOKUP(B:B,UAT!B:B,1,0) -> #N/A | G37: =VLOOKUP(D:D,UAT!C:C,1,0) -> #N/A | H37: =VLOOKUP(C:C,UAT!D:D,1,0) -> #N/A
C38: Critical Care Unit/Cardiac ICU/CCU/ICCU | D38: 1014382 | E38: =VLOOKUP(A:A,UAT!A:A,1,0) -> #N/A | F38: =VLOOKUP(B:B,UAT!B:B,1,0) -> #N/A | G38: =VLOOKUP(D:D,UAT!C:C,1,0) -> #N/A | H38: =VLOOKUP(C:C,UAT!D:D,1,0) -> #N/A
C39: Paediatric ICU/NICU | D39: 1014383 | E39: =VLOOKUP(A:A,UAT!A:A,1,0) -> #N/A | F39: =VLOOKUP(B:B,UAT!B:B,1,0) -> #N/A | G39: =VLOOKUP(D:D,UAT!C:C,1,0) -> #N/A | H39: =VLOOKUP(C:C,UAT!D:D,1,0) -> #N/A
C40: Surgical ICU | D40: 1014384 | E40: =VLOOKUP(A:A,UAT!A:A,1,0) -> #N/A | F40: =VLOOKUP(B:B,UAT!B:B,1,0) -> #N/A | G40: =VLOOKUP(D:D,UAT!C:C,1,0) -> #N/A | H40: =VLOOKUP(C:C,UAT!D:D,1,0) -> #N/A
...

Sheet Sheet4
H3: Create New in UAT (Count)
G4: Options | H4: Main Bill Type | I4: Sub Bill Type | J4: Condition
G5: 1 (Prefered) | H5: 32 | I5: 88 | J5: Name and ID both should match with LIVE
G6: 2 | H6: 20 | I6: 53 | J6: ID matching with LIVE not required
